<?xml version="1.0" ?>
<!-- =================================================================================== -->
<!-- |    This document was autogenerated by xacro from robot.urdf.xacro               | -->
<!-- |    EDITING THIS FILE BY HAND IS NOT RECOMMENDED                                 | -->
<!-- =================================================================================== -->
<robot name="mp500lwa4d_robot">
  <!--+++++++++ Material +++++++++-->
  <material name="Black">
    <color rgba="0.0 0.0 0.0 1.0"/>
  </material>
  <material name="Blue">
    <color rgba="0.0 0.0 0.8 1.0"/>
  </material>
  <material name="Green">
    <color rgba="0.0 0.8 0.0 1.0"/>
  </material>
  <material name="Grey">
    <color rgba="0.7 0.7 0.7 1.0"/>
  </material>
  <material name="Grey2">
    <color rgba="0.9 0.9 0.9 1.0"/>
  </material>
  <material name="Red">
    <color rgba="0.8 0.0 0.0 1.0"/>
  </material>
  <material name="White">
    <color rgba="1.0 1.0 1.0 1.0"/>
  </material>
  <material name="Yellow">
    <color rgba="1.0 1.0 0 1.0"/>
  </material>
  <material name="LightGrey">
    <color rgba="0.7 0.7 0.7 1.0"/>
  </material>
  <material name="DarkGrey">
    <color rgba="0.4 0.4 0.4 1.0"/>
  </material>
  <material name="DarkGolden">
    <color rgba="0.4 0.4 0.3 1.0"/>
  </material>
  <!--++++++++++++++++++base_link+++++++++++++++++++++-->
  <joint name="base_footprint_joint" type="fixed">
    <origin rpy="0 0 0" xyz="0 0 0"/>
    <parent link="base_footprint"/>
    <child link="base_link"/>
  </joint>
  <link name="base_footprint">
    <visual>
      <origin rpy="0 0 0" xyz="0 0 0"/>
      <geometry>
        <box size="0.001 0.001 0.001"/>
      </geometry>
    </visual>
  </link>
  <link name="base_link">
    <inertial>
      <mass value="67.010"/>
      <!--<origin xyz="0 0 0.216" rpy="0 0 0"/>-->
      <inertia ixx="0.54" ixy="0.0" ixz="0.0" iyy="1.08" iyz="0.0" izz="1.23" />
      <!--<inertia ixx="1" ixy="0.0" ixz="0.0" iyy="1" iyz="0.0" izz="1"/>-->
    </inertial>
    <visual name="body">
      <!--origin xyz="0.0 0.0 0.234" rpy="0 0 1.57" /-->
      <!-- for cylinder -->
      <origin rpy="0 0 -1.57" xyz="-0.160 0.0 0.08"/>
      <!-- for STL -->
      <geometry>
        <mesh filename="meshes/MP500-BODY.STL" scale="0.01 0.01 0.01"/>
        <!--cylinder length="0.381" radius="0.2545"/-->
        <!--box size="0.445 0.277 0.17"/-->
      </geometry>
      <material name="Grey"/>
    </visual>
    <collision name="body_collision">
      <origin rpy="0 0 -1.57" xyz="-0.160 0.0 0.08"/>
      <geometry>
          <mesh filename="meshes/MP500-BODY.STL" scale="0.01 0.01 0.01"/>
        <!--<box size="0.570 0.676 0.300"/>-->
          <!--<box size="0.830 0.600 0.400"/>-->
      </geometry>
    </collision>
  </link>
  <!--+++++++++++++++wheel_left_link++++++++++++++++++-->
  <link name="wheel_left_link" type="wheel">
      <contact>
      <lateral_friction value="1.0"/>
      <rolling_friction value="0.0"/>
      <stiffness value="30000"/>
      <damping value="1000"/>
    </contact>
    <inertial>
      <mass value="1.5"/>
      <origin rpy="0 0 0" xyz="0 0 0"/>
      <inertia ixx="0.0045" ixy="0" ixz="0" iyy="0.0078" iyz="0" izz="0.0045"/>
    </inertial>
    <visual>
      <origin rpy="0 0 -1.57" xyz="0 0 0"/>
      <geometry>
        <mesh filename="meshes/MP500-WHEEL.STL" scale="0.01 0.01 0.01"/>
      </geometry>
      <material name="Black"/>
    </visual>
    <collision>
      <origin rpy="0 1.57 -1.57" xyz="0 0 0"/>
      <geometry>
        <cylinder length="0.085" radius="0.125"/>
      </geometry>
    </collision>
  </link>
  <!--+++++++++++++++wheel_left_joint+++++++++++++++++-->
  <joint name="wheel_left_joint" type="continuous">
    <origin rpy="0 0 0" xyz="-0.155 0.255 0.13"/>
    <axis xyz="0 1 0"/>
    <!--<limit effort="1000.0" lower="-1e+16" upper="1e+16" velocity="3.5"/>
    	<joint_properties damping="0.0" friction="0.0" />-->
    <limit effort="500" velocity="5"/>
    <dynamics damping="0.0" friction="0.0"/>
    <parent link="base_link"/>
    <child link="wheel_left_link"/>
  </joint>
  <!--+++++++++++++++wheel_right_link+++++++++++++++++-->
  <!--Mesh Volume is 3587.704102
Mesh Surface is 1876.550415
Thin shell barycenter -25.340059 -0.000027 4.499997
Center of Mass is -25.340000 -0.000164 4.500009
Inertia Tensor is :
| 322624.937500 -0.068522 -1.293689 |
| -0.068522 179104.328125 -1.342927 |
| -1.293689 -1.342927 179079.796875 |
Principal axes are :
| 1.000000 -0.000000 0.000009 |
| -0.000000 0.998514 0.054499 |
| -0.000009 -0.054499 0.998514 |
axis momenta are :
| 322624.937500 179104.406250 179079.718750 |
Mesh Volume is 0.000000
Mesh Surface is 0.000019
Thin shell barycenter -0.002534 -0.000000 0.000450
Center of Mass is -0.002534 -0.000000 0.000450
Inertia Tensor is :
| 0.000000 -0.000000 -0.000000 |
| -0.000000 0.000000 -0.000000 |
| -0.000000 -0.000000 0.000000 |
Principal axes are :
| 1.000000 -0.000000 0.000009 |
| -0.000000 0.998526 0.054276 |
| -0.000009 -0.054276 0.998526 |
axis momenta are :
| 0.000000 0.000000 0.000000 | -->
  <link name="wheel_right_link" type="wheel">
      <contact>
      <lateral_friction value="1.0"/>
      <rolling_friction value="0.0"/>
      <stiffness value="30000"/>
      <damping value="1000"/>
    </contact>
    <inertial>
      <mass value="1.5"/>
      <origin rpy="0 0 0" xyz="0 0 0"/>
      <!--inertia ixx="0.0051" ixy="0" ixz="0" iyy="0.0051" iyz="0" izz="0.009" /-->
      <inertia ixx="0.0045" ixy="0" ixz="0" iyy="0.0078" iyz="0" izz="0.0045"/>
    </inertial>
    <visual>
      <origin rpy="0 0 -1.57" xyz="0 0 0"/>
      <geometry>
        <mesh filename="meshes/MP500-WHEEL.STL" scale="0.01 0.01 0.01"/>
      </geometry>
      <material name="Black"/>
    </visual>
    <collision>
      <origin rpy="0 1.57 -1.57" xyz="0 0 0"/>
      <geometry>
        <cylinder length="0.085" radius="0.125"/>
      </geometry>
    </collision>
  </link>
  <!--++++++++++++wheel_right_joint++++++++++++++-->
  <joint name="wheel_right_joint" type="continuous">
    <origin rpy="0 0 0" xyz="-0.155 -0.255 0.13"/>
    <axis xyz="0 1 0"/>
    <!--<limit effort="1000.0" lower="-1e+16" upper="1e+16" velocity="3.5"/>
    	<joint_properties damping="0.0" friction="0.0" />-->
    <!--<limit effort="500" velocity="5"/>
    <dynamics damping="0.0" friction="0.0"/>-->
    <parent link="base_link"/>
    <child link="wheel_right_link"/>
  </joint>
  <!--+++++++++++++++ wheel_hanger+++++++++++++++-->
  <link name="hanger">
    <inertial>
      <mass value="0.01"/>
      <origin rpy="0 0 0" xyz="0 0 0"/>
      <inertia ixx="0.0013" ixy="0" ixz="0" iyy="0.0013" iyz="0" izz="0.0013"/>
    </inertial>
    <visual>
      <origin rpy="0 0 -1.57" xyz="0 0 0"/>
      <geometry>
        <mesh filename="meshes/HANGER-WHEEL.STL" scale="0.01 0.01 0.01"/>
      </geometry>
      <material name="Grey"/>
    </visual>
    <collision>
      <origin rpy="0 0 -1.57" xyz="0 0 0"/>
      <geometry>
        <mesh filename="meshes/HANGER-WHEEL.STL" scale="0.01 0.01 0.01"/>
          <!--<sphere radius="0.12"/>-->
      </geometry>
    </collision>
  </link>
  <joint name="hanger_joint" type="fixed">
    <origin rpy="0 0 0" xyz="0.255 0 0.11"/>
    <axis xyz="0 0 1"/>
    <parent link="base_link"/>
    <child link="hanger"/>
  </joint>
  <joint name="arm_podest_joint" type="fixed">
    <origin rpy="0 0 0" xyz="0.19 0 0.36"/>
    <parent link="base_link"/>
    <child link="arm_podest_link"/>
  </joint>
  <link name="arm_podest_link">
    <inertial>
      <mass value="0.01"/>
      <origin xyz="0 0 0"/>
      <inertia ixx="0.001" ixy="0.0" ixz="0.0" iyy="0.001" iyz="0.0" izz="0.001"/>
    </inertial>
    <visual>
      <geometry>
        <mesh filename="meshes/arm_podest_link.stl"/>
      </geometry>
      <material name="LightGrey"/>
    </visual>
    <collision>
      <geometry>
        <mesh filename="meshes/arm_podest_link.stl"/>
      </geometry>
    </collision>
  </link>
  <joint name="arm_base_joint" type="fixed">
    <origin rpy="0 0 0" xyz="0 0 0.140"/>
    <axis xyz="0 0 1"/>
    <parent link="arm_podest_link"/>
    <child link="arm_base_link"/>
  </joint>
  <link name="arm_base_link">
    <!--xacro:default_inertial/-->
    <inertial>
      <mass value="0.01"/>
      <origin xyz="0 0 0"/>
      <inertia ixx="0.001" ixy="0.0" ixz="0.0" iyy="0.001" iyz="0.0" izz="0.001"/>
    </inertial>
  </link>
  <!-- joint between arm_base_link and arm_1_link -->
  <joint name="arm_1_joint" type="revolute">
    <origin rpy="0 0 0" xyz="0 0 0"/>
    <axis xyz="0 0 1"/>
    <parent link="arm_base_link"/>
    <child link="arm_1_link"/>
    <limit effort="216" lower="-3.12159265359" upper="3.12159265359" velocity="0.43633"/>
    <dynamics damping="0.0" friction="0.0"/>
  </joint>
  <!-- arm_1_link-->
  <link name="arm_1_link">
    <inertial>
      <mass value="0.01"/>
      <origin xyz="0 0 0"/>
      <inertia ixx="0.001" ixy="0.0" ixz="0.0" iyy="0.001" iyz="0.0" izz="0.001"/>
    </inertial>
    <!--
            <xacro:cylinder_inertial radius="0.06" length="0.150" mass="3.6">
                <origin xyz="0 0 0.02" rpy="0 0 0"/>
            </xacro:cylinder_inertial>
            -->
    <visual>
      <geometry>
        <mesh filename="meshes/arm_1_link.stl"/>
      </geometry>
      <material name="LightGrey"/>
    </visual>
    <collision>
      <geometry>
        <mesh filename="meshes/arm_1_link.stl"/>
      </geometry>
    </collision>
  </link>
  <!-- joint between arm_1_link and arm_2_link -->
  <joint name="arm_2_joint" type="revolute">
    <origin rpy="-1.57079632679 -1.57079632679 0" xyz="0 0 0.24"/>
    <axis xyz="0 0 1"/>
    <parent link="arm_1_link"/>
    <child link="arm_2_link"/>
    <limit effort="216" lower="-2.12" upper="2.12" velocity="0.43633"/>
    <dynamics damping="0.9" friction="0.08"/>
  </joint>
  <!-- arm_2_link -->
  <link name="arm_2_link">
    <inertial>
      <mass value="0.01"/>
      <origin xyz="0 0 0"/>
      <inertia ixx="0.001" ixy="0.0" ixz="0.0" iyy="0.001" iyz="0.0" izz="0.001"/>
    </inertial>
    <!--
            <xacro:cylinder_inertial radius="0.06" length="0.150" mass="2.0">
                <origin xyz="0 0 0" rpy="0 0 0"/>
            </xacro:cylinder_inertial>
            -->
    <visual>
      <geometry>
        <mesh filename="meshes/arm_2_link.stl"/>
      </geometry>
      <material name="Black"/>
    </visual>
    <collision>
      <geometry>
        <mesh filename="meshes/arm_2_link_collision.stl"/>
      </geometry>
    </collision>
  </link>
  <!-- joint between arm_2_link and arm_3_link -->
  <joint name="arm_3_joint" type="revolute">
    <origin rpy="1.57079632679 0 1.57079632679" xyz="0 0 0"/>
    <axis xyz="0 0 1"/>
    <parent link="arm_2_link"/>
    <child link="arm_3_link"/>
    <limit effort="81.5" lower="-3.12159265359" upper="3.12159265359" velocity="0.4189"/>
    <dynamics damping="0.0" friction="0.0"/>
  </joint>
  <!-- arm_3_link -->
  <link name="arm_3_link">
    <inertial>
      <mass value="0.01"/>
      <origin xyz="0 0 0"/>
      <inertia ixx="0.001" ixy="0.0" ixz="0.0" iyy="0.001" iyz="0.0" izz="0.001"/>
    </inertial>
    <!--
            <xacro:cylinder_inertial radius="0.06" length="0.2" mass="2.0">
                <origin xyz="0.0 0 -0.2" rpy="0 0 0"/>
            </xacro:cylinder_inertial>
            -->
    <visual>
      <geometry>
        <mesh filename="meshes/arm_3_link.stl"/>
      </geometry>
      <material name="LightGrey"/>
    </visual>
    <collision>
      <geometry>
        <mesh filename="meshes/arm_3_link_collision.stl"/>
      </geometry>
    </collision>
  </link>
  <!-- joint between arm_3_link and arm_4_link -->
  <joint name="arm_4_joint" type="revolute">
    <origin rpy="-1.57079632679 -1.57079632679 0" xyz="0 0 0.328"/>
    <axis xyz="0 0 1"/>
    <parent link="arm_3_link"/>
    <child link="arm_4_link"/>
    <limit effort="81.5" lower="-2.16" upper="2.16" velocity="0.4189"/>
    <dynamics damping="0.9" friction="0.08"/>
  </joint>
  <!--arm_4_link -->
  <link name="arm_4_link">
    <inertial>
      <mass value="0.01"/>
      <origin xyz="0 0 0"/>
      <inertia ixx="0.001" ixy="0.0" ixz="0.0" iyy="0.001" iyz="0.0" izz="0.001"/>
    </inertial>
    <!--
            <xacro:cylinder_inertial radius="0.06" length="0.150" mass="1.2">
                <origin xyz="0 0 0" rpy="0 0 0"/>
            </xacro:cylinder_inertial>
            -->
    <visual>
      <geometry>
        <mesh filename="meshes/arm_4_link.stl"/>
      </geometry>
      <material name="Black"/>
    </visual>
    <collision>
      <geometry>
        <mesh filename="meshes/arm_4_link_collision.stl"/>
      </geometry>
    </collision>
  </link>
  <!-- joint between arm_4_link and arm_5_link -->
  <joint name="arm_5_joint" type="revolute">
    <origin rpy="1.57079632679 0 1.57079632679" xyz="0 0 0"/>
    <axis xyz="0 0 1"/>
    <parent link="arm_4_link"/>
    <child link="arm_5_link"/>
    <limit effort="20.7" lower="-3.12159265359" upper="3.12159265359" velocity="0.43633"/>
    <dynamics damping="0.0" friction="0.0"/>
  </joint>
  <!-- arm_5_link -->
  <link name="arm_5_link">
    <inertial>
      <mass value="0.01"/>
      <origin xyz="0 0 0"/>
      <inertia ixx="0.001" ixy="0.0" ixz="0.0" iyy="0.001" iyz="0.0" izz="0.001"/>
    </inertial>
    <!--
            <xacro:cylinder_inertial radius="0.06" length="0.15" mass="1.2">
                <origin xyz="0 0 -0.18" rpy="0 0 0"/>
            </xacro:cylinder_inertial>
            -->
    <visual>
      <geometry>
        <mesh filename="meshes/arm_5_link.stl"/>
      </geometry>
      <material name="LightGrey"/>
    </visual>
    <collision>
      <geometry>
        <mesh filename="meshes/arm_5_link_collision.stl"/>
      </geometry>
    </collision>
  </link>
  <!-- joint between arm_5_link and arm_6_link -->
  <joint name="arm_6_joint" type="revolute">
    <origin rpy="-1.57079632679 -1.57079632679 0" xyz="0 0 0.323"/>
    <axis xyz="0 0 1"/>
    <parent link="arm_5_link"/>
    <child link="arm_6_link"/>
    <limit effort="15" lower="-2.94" upper="2.94" velocity="1.2566"/>
    <dynamics damping="0.0" friction="0.0"/>
  </joint>
  <!-- arm_6_link -->
  <link name="arm_6_link">
    <inertial>
      <mass value="0.01"/>
      <origin xyz="0 0 0"/>
      <inertia ixx="0.001" ixy="0.0" ixz="0.0" iyy="0.001" iyz="0.0" izz="0.001"/>
    </inertial>
    <!--
            <xacro:sphere_inertial radius="0.05" mass="1.9">
                <origin xyz="0 0 0" rpy="0 0 0"/>
            </xacro:sphere_inertial>
            -->
    <visual>
      <geometry>
        <mesh filename="meshes/arm_6_link.stl"/>
      </geometry>
      <material name="Black"/>
    </visual>
    <collision>
      <geometry>
        <mesh filename="meshes/arm_6_link_collision.stl"/>
      </geometry>
    </collision>
  </link>
  <!-- joint between arm_6_link and arm_7_link -->
  <joint name="arm_7_joint" type="revolute">
    <origin rpy="1.57079632679 0 1.57079632679" xyz="0 0 0"/>
    <axis xyz="0 0 1"/>
    <parent link="arm_6_link"/>
    <child link="arm_7_link"/>
    <limit effort="15" lower="-2.94" upper="2.94" velocity="1.2566"/>
  </joint>
  <!--arm_7_link -->
  <link name="arm_7_link">
    <inertial>
      <mass value="0.01"/>
      <origin xyz="0 0 0"/>
      <inertia ixx="0.001" ixy="0.0" ixz="0.0" iyy="0.001" iyz="0.0" izz="0.001"/>
    </inertial>
    <!--
            <xacro:cylinder_inertial radius="0.03" length="0.035" mass="0.05">
                <origin xyz="0 0 0.06" rpy="0 0 0"/>
            </xacro:cylinder_inertial>
            -->
    <visual>
      <geometry>
        <mesh filename="meshes/arm_7_link.stl"/>
      </geometry>
      <material name="LightGrey"/>
    </visual>
    <collision>
      <geometry>
        <mesh filename="meshes/arm_7_link.stl"/>
      </geometry>
    </collision>
  </link>
  <!--joint name="gripper_podest_joint" type="fixed">
    <origin rpy="0 0 0" xyz="0 0 0.0824"/>
    <parent link="arm_7_link"/>
    <child link="gripper_podest_link"/>
  </joint>
  <link name="gripper_podest_link">
    <inertial>
      <mass value="0.001"/>
      <origin xyz="0 0 0"/>
      <inertia ixx="0.0001" ixy="0.0" ixz="0.0" iyy="0.0001" iyz="0.0" izz="0.0001"/>
    </inertial>
    <visual>
      <origin rpy="0 3.14159265359 0" xyz="0 0 0"/>
      <geometry>
        <mesh filename="meshes/arm_base_link.stl"/>
      </geometry>
      <material name="black">
        <color rgba="0 0 0 1"/>
      </material>
    </visual>
    <collision>
      <origin rpy="0 3.14159265359 0" xyz="0 0 0"/>
      <geometry>
        <mesh filename="meshes/arm_base_link.stl"/>
      </geometry>
    </collision>
  </link>
  <joint name="gripper_palm_joint" type="fixed">
    <origin rpy="0 0 0" xyz="0 0 0"/>
    <parent link="gripper_podest_link"/>
    <child link="gripper_palm_link"/>
  </joint>
  <link name="gripper_palm_link">
    <inertial>
      <origin rpy="0 0 0" xyz="0 0 0"/>
      <mass value="0.001"/>
      <inertia ixx="0.0001" ixy="0" ixz="0" iyy="0.0001" iyz="0" izz="0.0001"/>
    </inertial>
    <visual>
      <geometry>
        <mesh filename="meshes/pg70.dae"/>
      </geometry>
    </visual>
    <collision>
      <origin rpy="0 0 0" xyz="0 0 0.03145"/>
      <geometry>
        <box size="0.082 0.114 0.080"/>
      </geometry>
    </collision>
  </link>
  <joint name="gripper_finger_left_joint" type="prismatic">
    <origin rpy="0 0 0" xyz="0 -0.005 0.1139"/>
    <parent link="gripper_palm_link"/>
    <child link="gripper_finger_left_link"/>
    <axis xyz="0 1 0"/>
    <limit effort="10" lower="-0.0301" upper="-0.005" velocity="0.041"/>
    <dynamics damping="0.08" friction="0.08"/>
  </joint>
  <link name="gripper_finger_left_link">
    <inertial>
      <origin rpy="0 0 0" xyz="0 0 0"/>
      <mass value="0.001"/>
      <inertia ixx="0.0001" ixy="0" ixz="0" iyy="0.0001" iyz="0" izz="0.0001"/>
    </inertial>
    <visual>
      <geometry>
        <box size="0.03 0.01 0.08"/>
      </geometry>
      <material name="black">
        <color rgba="0 0 0 1"/>
      </material>
    </visual>
    <collision>
      <geometry>
        <box size="0.03 0.01 0.08"/>
      </geometry>
    </collision>
  </link>
  <joint name="gripper_finger_right_joint" type="prismatic">
    <origin rpy="-0 0 0" xyz="0 0.005 0.1139"/>
    <parent link="gripper_palm_link"/>
    <child link="gripper_finger_right_link"/>
    <axis xyz="0 1 0"/>
    <limit effort="10" lower="0.005" upper="0.0301" velocity="0.041"/>
    <dynamics damping="0.08" friction="0.08"/>
  </joint>
  <link name="gripper_finger_right_link">
    <inertial>
      <origin rpy="0 0 0" xyz="0 0 0"/>
      <mass value="0.001"/>
      <inertia ixx="0.0001" ixy="0" ixz="0" iyy="0.0001" iyz="0" izz="0.0001"/>
    </inertial>
    <visual>
      <geometry>
        <box size="0.03 0.01 0.08"/>
      </geometry>
      <material name="black">
        <color rgba="0 0 0 1"/>
      </material>
    </visual>
    <collision>
      <geometry>
        <box size="0.03 0.01 0.08"/>
      </geometry>
    </collision>
  </link>
  <link name="grasping_frame"/>
  <joint name="grasping_frame_joint" type="fixed">
    <parent link="arm_7_link"/>
    <child link="grasping_frame"/>
    <origin rpy="0 0 0" xyz="0 0 0.0824"/>
  </joint-->
  <joint name="laserscanner_front_joint" type="fixed">
    <axis xyz="0 0 1"/>
    <origin rpy="0 0 0" xyz="-0.39 0 0.281"/>
    <parent link="base_link"/>
    <child link="laserscanner_front_link"/>
  </joint>
  <link name="laserscanner_front_link" type="laser">
    <inertial>
      <mass value="0.01"/>
      <origin rpy="3.14 0 -1.57" xyz="0 0 0"/>
      <inertia ixx="0.001" ixy="0" ixz="0" iyy="0.001" iyz="0" izz="0.001"/>
    </inertial>
    <visual>
      <origin rpy="3.14 0 -1.57" xyz="0 0 -0.04"/>
      <geometry>
        <!--cylinder length="0.154" radius="0.053" /-->
        <mesh filename="meshes/SICK-S300.STL"/>
      </geometry>
      <material name="Gazebo/Yellow"/>
    </visual>
    <collision>
      <origin rpy="3.14 0 -1.57" xyz="0 0 0"/>
      <geometry>
        <cylinder length="0.154" radius="0.053"/>
      </geometry>
    </collision>
  </link>
  <!-- Base Link -->
  <gazebo reference="base_footprint">
    <material value="Gazebo/Grey"/>
  </gazebo>
  <gazebo reference="base_link">
    <gravity>true</gravity>
    <material value="Gazebo/Grey"/>
  </gazebo>
  <!-- Left Wheel -->
  <gazebo reference="wheel_left_link">
    <gravity>true</gravity>
    <mu1>0.1</mu1>
    <mu2>0.1</mu2>
    <kp>1000000.0</kp>
    <kd>100.0</kd>
    <fdir1>0 0 1</fdir1>
    <material value="Gazebo/Blue"/>
  </gazebo>
  <!-- Right Wheel -->
  <gazebo reference="wheel_right_link">
    <gravity>true</gravity>
    <mu1>0.1</mu1>
    <mu2>0.1</mu2>
    <kp>1000000.0</kp>
    <kd>100.0</kd>
    <fdir1>0 0 1</fdir1>
    <material value="Gazebo/Blue"/>
  </gazebo>
  <!-- Castor -->
  <gazebo reference="hanger">
    <gravity>true</gravity>
    <mu1>0.1</mu1>
    <mu2>0.1</mu2>
    <kp>1000000.0</kp>
    <kd>100.0</kd>
    <material value="Gazebo/Grey"/>
  </gazebo>
  <!--<gazebo reference="castor_front">
          <gravity>true</gravity>
          <mu1>0.1</mu1>
          <mu2>0.1</mu2>
          <kp>1000000.0</kp>
          <kd>100.0</kd>
          <material value="Gazebo/Grey"/>
      </gazebo>-->
  <gazebo reference="arm_base_link">
    <gravity>true</gravity>
    <self_collide>false</self_collide>
    <material value="Gazebo/Black"/>
  </gazebo>
  <gazebo reference="arm_1_link">
    <gravity>true</gravity>
    <self_collide>false</self_collide>
    <material value="Gazebo/Grey"/>
  </gazebo>
  <gazebo reference="arm_2_link">
    <gravity>true</gravity>
    <self_collide>false</self_collide>
    <material value="Gazebo/Black"/>
  </gazebo>
  <gazebo reference="arm_3_link">
    <gravity>true</gravity>
    <self_collide>false</self_collide>
    <material value="Gazebo/Grey"/>
  </gazebo>
  <gazebo reference="arm_4_link">
    <gravity>true</gravity>
    <self_collide>false</self_collide>
    <material value="Gazebo/Black"/>
  </gazebo>
  <gazebo reference="arm_5_link">
    <gravity>true</gravity>
    <self_collide>false</self_collide>
    <material value="Gazebo/Grey"/>
  </gazebo>
  <gazebo reference="arm_6_link">
    <gravity>true</gravity>
    <self_collide>false</self_collide>
    <material value="Gazebo/Black"/>
  </gazebo>
  <gazebo reference="arm_7_link">
    <gravity>true</gravity>
    <self_collide>false</self_collide>
    <material value="Gazebo/Grey"/>
  </gazebo>
  <!--gazebo reference="gripper_podest_link">
    <gravity>true</gravity>
    <self_collide>false</self_collide>
    <material>Gazebo/Black</material>
  </gazebo>
  <gazebo reference="gripper_palm_link">
    <gravity>true</gravity>
    <self_collide>true</self_collide>
    <material>Gazebo/Black</material>
  </gazebo>
  <gazebo reference="gripper_finger_left_link">
    <gravity>true</gravity>
    <self_collide>false</self_collide>
    <material>Gazebo/Grey</material>
  </gazebo>
  <gazebo reference="gripper_finger_right_link">
    <gravity>true</gravity>
    <self_collide>false</self_collide>
    <material>Gazebo/Grey</material>
  </gazebo-->
  <!--gazebo reference="laserscanner_front_link">
    <material value="Gazebo/Grey"/>
  </gazebo>
  <gazebo reference="laserscanner_front_link">
    <sensor name="rplidar" type="ray">
      <pose>0 0 0 0 0 0</pose>
      <visualize>false</visualize>
      <update_rate>5.5</update_rate>
      <ray>
        <scan>
          <horizontal>
            <samples>360</samples>
            <resolution>1</resolution>
            <min_angle>-3</min_angle>
            <max_angle>3</max_angle>
          </horizontal>
        </scan>
        <range>
          <min>0.10</min>
          <max>6.0</max>
          <resolution>0.01</resolution>
        </range>
        <noise>
          <type>gaussian</type>
          <mean>0.0</mean>
          <stddev>0.01</stddev>
        </noise>
      </ray>
      <plugin filename="libgazebo_ros_laser.so" name="gazebo_rplidar">
        <topicName>/scan</topicName>
        <frameName>laser_link</frameName>
      </plugin>
    </sensor>
  </gazebo-->
  <transmission name="wheel_left_trans">
    <type>transmission_interface/SimpleTransmission</type>
    <joint name="wheel_left_joint">
      <hardwareInterface>hardware_interface/VelocityJointInterface</hardwareInterface>
    </joint>
    <actuator name="wheel_left_motor">
      <!--hardwareInterface>hardware_interface/EffortJointInterface</hardwareInterface-->
      <mechanicalReduction>1</mechanicalReduction>
    </actuator>
  </transmission>
  <transmission name="wheel_right_trans">
    <type>transmission_interface/SimpleTransmission</type>
    <joint name="wheel_right_joint">
      <hardwareInterface>hardware_interface/VelocityJointInterface</hardwareInterface>
    </joint>
    <actuator name="wheel_right_motor">
      <!--hardwareInterface>hardware_interface/EffortJointInterface</hardwareInterface-->
      <mechanicalReduction>1</mechanicalReduction>
    </actuator>
  </transmission>
  <transmission name="arm_1_trans">
    <type>transmission_interface/SimpleTransmission</type>
    <joint name="arm_1_joint">
      <hardwareInterface>hardware_interface/PositionJointInterface</hardwareInterface>
    </joint>
    <actuator name="arm_1_motor">
      <hardwareInterface>hardware_interface/EffortJointInterface</hardwareInterface>
      <mechanicalReduction>1</mechanicalReduction>
    </actuator>
  </transmission>
  <transmission name="arm_2_trans">
    <type>transmission_interface/SimpleTransmission</type>
    <joint name="arm_2_joint">
      <hardwareInterface>hardware_interface/PositionJointInterface</hardwareInterface>
    </joint>
    <actuator name="arm_2_motor">
      <hardwareInterface>hardware_interface/EffortJointInterface</hardwareInterface>
      <mechanicalReduction>1</mechanicalReduction>
    </actuator>
  </transmission>
  <transmission name="arm_3_trans">
    <type>transmission_interface/SimpleTransmission</type>
    <joint name="arm_3_joint">
      <hardwareInterface>hardware_interface/PositionJointInterface</hardwareInterface>
    </joint>
    <actuator name="arm_3_motor">
      <hardwareInterface>hardware_interface/EffortJointInterface</hardwareInterface>
      <mechanicalReduction>1</mechanicalReduction>
    </actuator>
  </transmission>
  <transmission name="arm_4_trans">
    <type>transmission_interface/SimpleTransmission</type>
    <joint name="arm_4_joint">
      <hardwareInterface>hardware_interface/PositionJointInterface</hardwareInterface>
    </joint>
    <actuator name="arm_4_motor">
      <hardwareInterface>hardware_interface/EffortJointInterface</hardwareInterface>
      <mechanicalReduction>1</mechanicalReduction>
    </actuator>
  </transmission>
  <transmission name="arm_5_trans">
    <type>transmission_interface/SimpleTransmission</type>
    <joint name="arm_5_joint">
      <hardwareInterface>hardware_interface/PositionJointInterface</hardwareInterface>
    </joint>
    <actuator name="arm_5_motor">
      <hardwareInterface>hardware_interface/EffortJointInterface</hardwareInterface>
      <mechanicalReduction>1</mechanicalReduction>
    </actuator>
  </transmission>
  <transmission name="arm_6_trans">
    <type>transmission_interface/SimpleTransmission</type>
    <joint name="arm_6_joint">
      <hardwareInterface>hardware_interface/PositionJointInterface</hardwareInterface>
    </joint>
    <actuator name="arm_6_motor">
      <hardwareInterface>hardware_interface/EffortJointInterface</hardwareInterface>
      <mechanicalReduction>1</mechanicalReduction>
    </actuator>
  </transmission>
  <transmission name="arm_7_trans">
    <type>transmission_interface/SimpleTransmission</type>
    <joint name="arm_7_joint">
      <hardwareInterface>hardware_interface/PositionJointInterface</hardwareInterface>
    </joint>
    <actuator name="arm_7_motor">
      <hardwareInterface>hardware_interface/EffortJointInterface</hardwareInterface>
      <mechanicalReduction>1</mechanicalReduction>
    </actuator>
  </transmission>
  <!--transmission name="gripper_finger_left_trans">
    <type>transmission_interface/SimpleTransmission</type>
    <joint name="gripper_finger_left_joint">
      <hardwareInterface>hardware_interface/PositionJointInterface</hardwareInterface>
    </joint>
    <actuator name="gripper_finger_left_motor">
      <hardwareInterface>hardware_interface/EffortJointInterface</hardwareInterface>
      <mechanicalReduction>1</mechanicalReduction>
    </actuator>
  </transmission>
  <transmission name="gripper_finger_right_trans">
    <type>transmission_interface/SimpleTransmission</type>
    <joint name="gripper_finger_right_joint">
      <hardwareInterface>hardware_interface/PositionJointInterface</hardwareInterface>
    </joint>
    <actuator name="gripper_finger_right_motor">
      <hardwareInterface>hardware_interface/EffortJointInterface</hardwareInterface>
      <mechanicalReduction>1</mechanicalReduction>
    </actuator>
  </transmission-->
  <!--gazebo>
    <plugin filename="libgazebo_ros_control.so" name="gazebo_ros_control">
      <robotNamespace>/mp500lwa4d</robotNamespace>
      <robotBaseFrame>base_footprint</robotBaseFrame>
    </plugin>
    <plugin filename="libgazebo_ros_diff_drive.so" name="differential_drive_controller">
      <robotNamespace>/</robotNamespace>
      <alwaysOn>true</alwaysOn>
      <updateRate>50</updateRate>
      <leftJoint>wheel_left_joint</leftJoint>
      <rightJoint>wheel_right_joint</rightJoint>
      <wheelSeparation>0.51</wheelSeparation>
      <wheelDiameter>0.25</wheelDiameter>
      <torque>100</torque>
      <commandTopic>/mobile_base_controller/cmd_vel</commandTopic>
      <odometryTopic>odom</odometryTopic>
      <odometryFrame>odom</odometryFrame>
      <robotBaseFrame>base_footprint</robotBaseFrame>
      <legacyMode>false</legacyMode>
      <rosDebugLevel>Debug</rosDebugLevel>
      <publishWheelTF>true</publishWheelTF>
      <publishWheelJointState>true</publishWheelJointState>
      <wheelAcceleration>10</wheelAcceleration>
      <wheelTorque>100</wheelTorque>
      <publishTf>1</publishTf>
      <odometrySource>encoder</odometrySource>
    </plugin>
  </gazebo-->
</robot>

